[2023-08-21 07:59:05,849] [citros.citros-None-None.get_access_token:414] [ERROR]: HTTP error occurred during get_access_token
[2023-08-21 07:59:05,854] [citros.citros-None-None.handle_exceptions:89] [ERROR]: Traceback (most recent call last):
  File "/usr/local/lib/python3.10/dist-packages/citros/citros.py", line 411, in get_access_token
    resp.raise_for_status()
  File "/home/ros/.local/lib/python3.10/site-packages/requests/models.py", line 1021, in raise_for_status
    raise HTTPError(http_error_msg, response=self)
requests.exceptions.HTTPError: 401 Client Error: Unauthorized for url: https://citros.io/api/gtoken
Traceback (most recent call last):
  File "/usr/local/lib/python3.10/dist-packages/citros/citros.py", line 411, in get_access_token
    resp.raise_for_status()
  File "/home/ros/.local/lib/python3.10/site-packages/requests/models.py", line 1021, in raise_for_status
    raise HTTPError(http_error_msg, response=self)
requests.exceptions.HTTPError: 401 Client Error: Unauthorized for url: https://citros.io/api/gtoken
